2025-05-24 12:12:11,023 | Level: ERROR | Module: views | Line: 1565 | Message: Role is required.
2025-05-24 12:15:39,408 | Level: ERROR | Module: views | Line: 1565 | Message: Role is required.
2025-05-24 12:15:39,411 | Level: ERROR | Module: views | Line: 1570 | Message: Email is required.
2025-05-24 12:15:39,412 | Level: ERROR | Module: views | Line: 1611 | Message: DOJ is required.
2025-05-24 12:15:39,413 | Level: ERROR | Module: views | Line: 1630 | Message: Department is required.
2025-05-24 12:15:39,413 | Level: ERROR | Module: views | Line: 1639 | Message: Designation is required.
2025-05-24 12:16:26,717 | Level: ERROR | Module: views | Line: 1565 | Message: Role is required.
2025-05-24 12:16:26,718 | Level: ERROR | Module: views | Line: 1570 | Message: Email is required.
2025-05-24 12:16:26,719 | Level: ERROR | Module: views | Line: 1611 | Message: DOJ is required.
2025-05-24 12:16:26,719 | Level: ERROR | Module: views | Line: 1630 | Message: Department is required.
2025-05-24 12:16:26,720 | Level: ERROR | Module: views | Line: 1639 | Message: Designation is required.
2025-05-24 15:27:27,581 | Level: ERROR | Module: log | Line: 248 | Message: Internal Server Error: /assets/add/
Traceback (most recent call last):
  File "C:\HR_Project\HR_Portal\HR_Portal\Lib\site-packages\django\core\handlers\exception.py", line 55, in inner
    response = get_response(request)
  File "C:\HR_Project\HR_Portal\HR_Portal\Lib\site-packages\django\core\handlers\base.py", line 197, in _get_response
    response = wrapped_callback(request, *callback_args, **callback_kwargs)
  File "C:\HR_Project\HR_Portal\HR_Portal\HR_App\views.py", line 3853, in add_asset
    return render(request, 'assets_templates/Assets_add.html', {'employees': employees})
2025-05-26 14:06:32,764 | Level: ERROR | Module: basehttp | Line: 213 | Message: "GET /error-log/ HTTP/1.1" 500 80836
2025-05-26 14:10:55,678 | Level: ERROR | Module: views | Line: 1763 | Message: Incorrect password.
2025-05-26 14:10:56,359 | Level: ERROR | Module: views | Line: 1763 | Message: Incorrect password.
2025-05-26 14:11:07,138 | Level: ERROR | Module: views | Line: 1759 | Message: No account found with this email.
2025-05-26 14:27:55,026 | Level: ERROR | Module: log | Line: 248 | Message: Internal Server Error: /assets/list/

2025-05-27 14:30:07,987 | Level: ERROR | Module: views | Line: 1781 | Message: Incorrect password.
2025-05-27 14:30:18,291 | Level: ERROR | Module: views | Line: 1781 | Message: Incorrect password.
2025-05-27 14:30:21,804 | Level: ERROR | Module: views | Line: 1781 | Message: Incorrect password.
2025-05-27 15:50:34,109 | Level: ERROR | Module: log | Line: 248 | Message: Internal Server Error: /delete/64/
Traceback (most recent call last):
  File "C:\HR_Project\HR_Portal\HR_Portal\Lib\site-packages\django\core\handlers\exception.py", line 55, in inner
    response = get_response(request)
  File "C:\HR_Project\HR_Portal\HR_Portal\Lib\site-packages\django\core\handlers\base.py", line 197, in _get_response
    response = wrapped_callback(request, *callback_args, **callback_kwargs)
  File "C:\HR_Project\HR_Portal\HR_Portal\HR_App\views.py", line 1325, in delete_employee
    logger.info(
    ~~~~~~~~~~~^
        "Employee Inactive",
        ^^^^^^^^^^^^^^^^^^^^
        extra={'action': 'Employee Inactive', 'message': f"Employee '{employee.name}' with ID {employee.id}."}
        ^^^^^^^^^^^^^^^^^^^^^^^^^^^^^^^^^^^^^^^^^^^^^^^^^^^^^^^^^^^^^^^^^^^^^^^^^^^^^^^^^^^^^^^^^^^^^^^^^^^^^^
    )
    ^
  File "C:\Users\acer\AppData\Local\Programs\Python\Python313\Lib\logging\__init__.py", line 1519, in info
    self._log(INFO, msg, args, **kwargs)
    ~~~~~~~~~^^^^^^^^^^^^^^^^^^^^^^^^^^^
  File "C:\Users\acer\AppData\Local\Programs\Python\Python313\Lib\logging\__init__.py", line 1662, in _log
    record = self.makeRecord(self.name, level, fn, lno, msg, args,
                             exc_info, func, extra, sinfo)
  File "C:\Users\acer\AppData\Local\Programs\Python\Python313\Lib\logging\__init__.py", line 1636, in makeRecord
    raise KeyError("Attempt to overwrite %r in LogRecord" % key)
KeyError: "Attempt to overwrite 'message' in LogRecord"
2025-05-27 15:50:34,117 | Level: ERROR | Module: basehttp | Line: 213 | Message: "GET /delete/64/ HTTP/1.1" 500 84079
2025-05-27 15:51:20,582 | Level: ERROR | Module: log | Line: 248 | Message: Internal Server Error: /delete/64/
Traceback (most recent call last):
  File "C:\HR_Project\HR_Portal\HR_Portal\Lib\site-packages\django\core\handlers\exception.py", line 55, in inner
    response = get_response(request)
  File "C:\HR_Project\HR_Portal\HR_Portal\Lib\site-packages\django\core\handlers\base.py", line 197, in _get_response
    response = wrapped_callback(request, *callback_args, **callback_kwargs)
  File "C:\HR_Project\HR_Portal\HR_Portal\HR_App\views.py", line 1325, in delete_employee
    logger.info(
    ~~~~~~~~~~~^
        "Employee Inactive",
        ^^^^^^^^^^^^^^^^^^^^
        extra={'action': 'Employee Inactive', 'message': f"Employee '{employee.name}' with ID {employee.id}."}
        ^^^^^^^^^^^^^^^^^^^^^^^^^^^^^^^^^^^^^^^^^^^^^^^^^^^^^^^^^^^^^^^^^^^^^^^^^^^^^^^^^^^^^^^^^^^^^^^^^^^^^^
    )
    ^
  File "C:\Users\acer\AppData\Local\Programs\Python\Python313\Lib\logging\__init__.py", line 1519, in info
    self._log(INFO, msg, args, **kwargs)
    ~~~~~~~~~^^^^^^^^^^^^^^^^^^^^^^^^^^^
  File "C:\Users\acer\AppData\Local\Programs\Python\Python313\Lib\logging\__init__.py", line 1662, in _log
    record = self.makeRecord(self.name, level, fn, lno, msg, args,
                             exc_info, func, extra, sinfo)
  File "C:\Users\acer\AppData\Local\Programs\Python\Python313\Lib\logging\__init__.py", line 1636, in makeRecord
    raise KeyError("Attempt to overwrite %r in LogRecord" % key)
KeyError: "Attempt to overwrite 'message' in LogRecord"
2025-05-27 15:51:20,591 | Level: ERROR | Module: basehttp | Line: 213 | Message: "GET /delete/64/ HTTP/1.1" 500 84036
2025-05-27 15:52:22,140 | Level: ERROR | Module: log | Line: 248 | Message: Internal Server Error: /delete/64/
Traceback (most recent call last):
  File "C:\HR_Project\HR_Portal\HR_Portal\Lib\site-packages\django\core\handlers\exception.py", line 55, in inner
    response = get_response(request)
  File "C:\HR_Project\HR_Portal\HR_Portal\Lib\site-packages\django\core\handlers\base.py", line 197, in _get_response
    response = wrapped_callback(request, *callback_args, **callback_kwargs)
  File "C:\HR_Project\HR_Portal\HR_Portal\HR_App\views.py", line 1325, in delete_employee
    logger.info(
    ~~~~~~~~~~~^
        "Employee Inactive",
        ^^^^^^^^^^^^^^^^^^^^
        extra={'action': 'Employee Inactive', 'message': f"Employee '{employee.name}' with ID {employee.id}."}
        ^^^^^^^^^^^^^^^^^^^^^^^^^^^^^^^^^^^^^^^^^^^^^^^^^^^^^^^^^^^^^^^^^^^^^^^^^^^^^^^^^^^^^^^^^^^^^^^^^^^^^^
    )
    ^
  File "C:\Users\acer\AppData\Local\Programs\Python\Python313\Lib\logging\__init__.py", line 1519, in info
    self._log(INFO, msg, args, **kwargs)
    ~~~~~~~~~^^^^^^^^^^^^^^^^^^^^^^^^^^^
  File "C:\Users\acer\AppData\Local\Programs\Python\Python313\Lib\logging\__init__.py", line 1662, in _log
    record = self.makeRecord(self.name, level, fn, lno, msg, args,
                             exc_info, func, extra, sinfo)
  File "C:\Users\acer\AppData\Local\Programs\Python\Python313\Lib\logging\__init__.py", line 1636, in makeRecord
    raise KeyError("Attempt to overwrite %r in LogRecord" % key)
KeyError: "Attempt to overwrite 'message' in LogRecord"
2025-05-27 15:52:22,144 | Level: ERROR | Module: basehttp | Line: 213 | Message: "GET /delete/64/ HTTP/1.1" 500 84036
2025-05-27 16:24:49,444 | Level: ERROR | Module: log | Line: 248 | Message: Internal Server Error: /Login/user/
Traceback (most recent call last):
  File "C:\HR_Project\HR_Portal\HR_Portal\Lib\site-packages\django\core\handlers\exception.py", line 55, in inner
    response = get_response(request)
  File "C:\HR_Project\HR_Portal\HR_Portal\Lib\site-packages\django\core\handlers\base.py", line 197, in _get_response
    response = wrapped_callback(request, *callback_args, **callback_kwargs)
  File "C:\HR_Project\HR_Portal\HR_Portal\Lib\site-packages\django\utils\decorators.py", line 192, in _view_wrapper
    result = _process_exception(request, e)
  File "C:\HR_Project\HR_Portal\HR_Portal\Lib\site-packages\django\utils\decorators.py", line 190, in _view_wrapper
    response = view_func(request, *args, **kwargs)
  File "C:\HR_Project\HR_Portal\HR_Portal\HR_App\views.py", line 1814, in Login_user
    logger.error("No account found with this email.")
    ^^^^^^
UnboundLocalError: cannot access local variable 'logger' where it is not associated with a value
2025-05-27 16:24:49,453 | Level: ERROR | Module: basehttp | Line: 213 | Message: "POST /Login/user/ HTTP/1.1" 500 79701
2025-05-27 16:27:16,307 | Level: ERROR | Module: views | Line: 1837 | Message: Incorrect password.
2025-05-27 17:21:29,318 | Level: ERROR | Module: log | Line: 248 | Message: Internal Server Error: /assets/add/
Traceback (most recent call last):
  File "C:\HR_Project\HR_Portal\HR_Portal\Lib\site-packages\django\core\handlers\exception.py", line 55, in inner
    response = get_response(request)
  File "C:\HR_Project\HR_Portal\HR_Portal\Lib\site-packages\django\core\handlers\base.py", line 197, in _get_response
    response = wrapped_callback(request, *callback_args, **callback_kwargs)
  File "C:\HR_Project\HR_Portal\HR_Portal\HR_App\views.py", line 4012, in add_asset
    'details': f"Employee '{Asset.allocated_to.name}' with ID {Asset.allocated_to.id} assest was Added"
                            ^^^^^^^^^^^^^^^^^^^^^^^
AttributeError: 'ForwardManyToOneDescriptor' object has no attribute 'name'
2025-05-27 17:21:29,323 | Level: ERROR | Module: basehttp | Line: 213 | Message: "POST /assets/add/ HTTP/1.1" 500 71496
2025-05-27 18:24:05,291 | Level: ERROR | Module: views | Line: 1814 | Message: No account found with this email.
2025-05-27 18:24:30,290 | Level: ERROR | Module: views | Line: 1814 | Message: No account found with this email.
2025-05-27 18:24:36,735 | Level: ERROR | Module: views | Line: 1814 | Message: No account found with this email.
2025-05-27 18:25:03,821 | Level: ERROR | Module: views | Line: 1844 | Message: Incorrect password.
2025-05-27 18:25:07,724 | Level: ERROR | Module: views | Line: 1844 | Message: Incorrect password.
2025-05-27 18:25:11,080 | Level: ERROR | Module: views | Line: 1844 | Message: Incorrect password.
2025-05-27 18:25:14,103 | Level: ERROR | Module: log | Line: 248 | Message: Internal Server Error: /Login/user/
Traceback (most recent call last):
  File "C:\HR_Project\HR_Portal\HR_Portal\Lib\site-packages\django\core\handlers\exception.py", line 55, in inner
    response = get_response(request)
  File "C:\HR_Project\HR_Portal\HR_Portal\Lib\site-packages\django\core\handlers\base.py", line 197, in _get_response
    response = wrapped_callback(request, *callback_args, **callback_kwargs)
  File "C:\HR_Project\HR_Portal\HR_Portal\Lib\site-packages\django\utils\decorators.py", line 192, in _view_wrapper
    result = _process_exception(request, e)
  File "C:\HR_Project\HR_Portal\HR_Portal\Lib\site-packages\django\utils\decorators.py", line 190, in _view_wrapper
    response = view_func(request, *args, **kwargs)
  File "C:\HR_Project\HR_Portal\HR_Portal\HR_App\views.py", line 1820, in Login_user
    if user.last_failed_login and datetime.now() < user.last_failed_login + timedelta(hours=2):
                                  ^^^^^^^^^^^^^^^^^^^^^^^^^^^^^^^^^^^^^^^^^^^^^^^^^^^^^^^^^^^^
TypeError: can't compare offset-naive and offset-aware datetimes
2025-05-27 18:25:14,112 | Level: ERROR | Module: basehttp | Line: 213 | Message: "POST /Login/user/ HTTP/1.1" 500 79962
2025-05-27 18:25:43,705 | Level: ERROR | Module: log | Line: 248 | Message: Internal Server Error: /Login/user/
Traceback (most recent call last):
  File "C:\HR_Project\HR_Portal\HR_Portal\Lib\site-packages\django\core\handlers\exception.py", line 55, in inner
    response = get_response(request)
  File "C:\HR_Project\HR_Portal\HR_Portal\Lib\site-packages\django\core\handlers\base.py", line 197, in _get_response
    response = wrapped_callback(request, *callback_args, **callback_kwargs)
  File "C:\HR_Project\HR_Portal\HR_Portal\Lib\site-packages\django\utils\decorators.py", line 192, in _view_wrapper
    result = _process_exception(request, e)
  File "C:\HR_Project\HR_Portal\HR_Portal\Lib\site-packages\django\utils\decorators.py", line 190, in _view_wrapper
    response = view_func(request, *args, **kwargs)
  File "C:\HR_Project\HR_Portal\HR_Portal\HR_App\views.py", line 1822, in Login_user
    remaining_time = lock_end_time - datetime.now()
                     ~~~~~~~~~~~~~~^~~~~~~~~~~~~~~~
TypeError: can't subtract offset-naive and offset-aware datetimes
2025-05-27 18:25:43,708 | Level: ERROR | Module: basehttp | Line: 213 | Message: "POST /Login/user/ HTTP/1.1" 500 80136
